Workbook

Sheet How to use
A1: Step | B1: What to do
A2: 1 | B2: Upload this file to Google Drive → Open with Google Sheets.
A3: 2 | B3: Every Sunday (10 min): add new rows to Money in, Money out, Rewards, Partners.
A4: 3 | B4: Type only the Date; the Month column fills itself. The Summary tab adds up by month by itself.
A5: 4 | B5: Every payment in Money in needs a UTR. Tick 'Checked in bank' only after you see it in the bank statement.
A6: 5 | B6: Every row in Money out needs a receipt saved in Drive: Hostelzy/Receipts/YYYY-MM/.
A7: 6 | B7: Budget caps are in the Budget tab. Red in the Summary = over the cap.
A8: 7 | B8: Plan and rules: docs/finance/plan.md in the repo.
A9: 8 | B9: Bills tab: every account the app needs, cost and due date. P&L tab: 6-month P&L at 20/50/100 hostels; edit yellow cells.
A10: 9 | B10: Budget v3 (2026-10-04): ₹10,000 a month to Hostelzy. Budget and P&L tabs use the lean numbers.

Sheet Bills
A1: Account | B1: Plan | C1: ₹ per month | D1: ₹ one time / yearly | E1: Due | F1: Status | G1: Unblocks
A2: Google Play Console | B2: One time $25 | C2: 0 | D2: 2900 | E2: Week of 6 Oct 2026 | F2: Not paid | G2: Play upload + 14-day closed test
A3: Supabase live (Mumbai) | B3: Free → Pro $25/mo | C3: 2900 | D3: 0 | E3: 1 Nov 2026 | F3: Free, running | G3: Backups, no pausing, real owners' data
A4: Supabase staging | B4: Free | C4: 0 | D4: 0 | E4: When Build needs it | F4: Not made | G4: Test SQL before the live run
A5: Firebase Spark | B5: Free | C5: 0 | D5: 0 | E5: - | F5: Running | G5: Google sign-in, push, crashes
A6: Firebase Blaze (SMS OTP) | B6: Pay per SMS, ₹1,000 alert | C6: 1000 | D6: 0 | E6: Nov 2026 (card) | F6: Card failed once | G6: Verified phones
A7: Google Maps SDK | B7: Pay as you go, ₹500 alert | C7: 0 | D7: 0 | E7: Before Play launch | F7: Not set up | G7: Real map at launch
A8: MapTiler (fallback only) | B8: Flex ~$25/mo | C8: 0 | D8: 0 | E8: Only if Google fails | F8: - | G8: Map without a Google card
A9: Domain hostelzy.in | B9: Yearly | C9: 0 | D9: 800 | E9: Oct 2026 | F9: Not bought | G9: Own web address
A10: GitHub Pro | B10: $4/mo when repo private | C10: 460 | D10: 0 | E10: When repo goes private | F10: Free | G10: Pages + build minutes on private repo
A11: Claude / AI tokens | B11: Your plan | C11: 10000 | D11: 0 | E11: Monthly | F11: Running | G11: Building the app
A12: WhatsApp Business app | B12: Free | C12: 0 | D12: 0 | E12: - | F12: - | G12: Owner chats
A13: Total | C13: =SUM(C2:C12) | D13: =SUM(D2:D12)

Sheet P&L
A1: Assumptions (edit the yellow cells) · Budget v3 lean plan, 2026-10-04
A2: Average price per paying hostel (₹) | B2: 750
A3: Trial converts to paid | B3: 0.7
A4: Commission per new paying owner (₹) | B4: 200
A5: Print per new hostel (₹) | B5: 150
A6: Rewards per paying hostel (₹, from month 3) | B6: 80
A7: Rewards cap (₹) | B7: 1000
A8: AI tokens (₹/month) | B8: 2300
A9: Tech month 1 (₹) | B9: 2400
A10: Supabase Pro from 10 paying hostels (₹) | B10: 2900
A12: Scenario: 20 hostels by March | H12: SMS ₹/mo | I12: 0 | J12: Hold pay ₹/mo | K12: 1000 | L12: Ads ₹/mo | M12: 0
A13: Line | B13: Oct 2026 | C13: Nov 2026 | D13: Dec 2026 | E13: Jan 2027 | F13: Feb 2027 | G13: Mar 2027
A14: Hostels live | B14: 15 | C14: 20 | D14: 20 | E14: 20 | F14: 20 | G14: 20
A15: Paying hostels | B15: 0 | C15: =ROUND($B$3*B14,0) | D15: =ROUND($B$3*C14,0) | E15: =ROUND($B$3*D14,0) | F15: =ROUND($B$3*E14,0) | G15: =ROUND($B$3*F14,0)
A16: Revenue | B16: =$B$2*B15 | C16: =$B$2*C15 | D16: =$B$2*D15 | E16: =$B$2*E15 | F16: =$B$2*F15 | G16: =$B$2*G15
A17: Tech | B17: =$B$9 | C17: =IF(C15>=10,$B$10,0)+$I$12 | D17: =IF(D15>=10,$B$10,0)+$I$12 | E17: =IF(E15>=10,$B$10,0)+$I$12 | F17: =IF(F15>=10,$B$10,0)+$I$12 | G17: =IF(G15>=10,$B$10,0)+$I$12
A18: AI tokens | B18: =$B$8 | C18: =$B$8 | D18: =$B$8 | E18: =$B$8 | F18: =$B$8 | G18: =$B$8
A19: Commission | B19: =0 | C19: =$B$4*MAX(0,C15-B15)+$K$12 | D19: =$B$4*MAX(0,D15-C15)+$K$12 | E19: =$B$4*MAX(0,E15-D15)+$K$12 | F19: =$B$4*MAX(0,F15-E15)+$K$12 | G19: =$B$4*MAX(0,G15-F15)+$K$12
A20: Print | B20: =$B$5*B14 | C20: =$B$5*MAX(0,C14-B14) | D20: =$B$5*MAX(0,D14-C14) | E20: =$B$5*MAX(0,E14-D14) | F20: =$B$5*MAX(0,F14-E14) | G20: =$B$5*MAX(0,G14-F14)
A21: Travel | B21: =2000 | C21: =IF(C14>B14,2000,1000) | D21: =IF(D14>C14,2000,1000) | E21: =IF(E14>D14,2000,1000) | F21: =IF(F14>E14,2000,1000) | G21: =IF(G14>F14,2000,1000)
A22: Ads | B22: =0 | C22: =$M$12 | D22: =$M$12 | E22: =$M$12 | F22: =$M$12 | G22: =$M$12
A23: Rewards | B23: =0 | C23: =0 | D23: =MIN($B$7,$B$6*D15) | E23: =MIN($B$7,$B$6*E15) | F23: =MIN($B$7,$B$6*F15) | G23: =MIN($B$7,$B$6*G15)
A24: Costs | B24: =SUM(B17:B23) | C24: =SUM(C17:C23) | D24: =SUM(D17:D23) | E24: =SUM(E17:E23) | F24: =SUM(F17:F23) | G24: =SUM(G17:G23)
A25: Profit / loss | B25: =B16-B24 | C25: =C16-C24 | D25: =D16-D24 | E25: =E16-E24 | F25: =F16-F24 | G25: =G16-G24
A26: P/L without AI tokens | B26: =B25+B18 | C26: =C25+C18 | D26: =D25+D18 | E26: =E25+E18 | F26: =F25+F18 | G26: =G25+G18
A27: Cumulative P/L | B27: =B25 | C27: =B27+C25 | D27: =C27+D25 | E27: =D27+E25 | F27: =E27+F25 | G27: =F27+G25
A28: Break-even month | B28: =IFERROR(INDEX($B$13:$G$13,MATCH(TRUE,INDEX($B$25:$G$25>=0,0),0)),"Not in 6 months")
A30: Scenario: 50 hostels by March | H30: SMS ₹/mo | I30: 0 | J30: Hold pay ₹/mo | K30: 1000 | L30: Ads ₹/mo | M30: 0
A31: Line | B31: Oct 2026 | C31: Nov 2026 | D31: Dec 2026 | E31: Jan 2027 | F31: Feb 2027 | G31: Mar 2027
A32: Hostels live | B32: 20 | C32: 30 | D32: 40 | E32: 50 | F32: 50 | G32: 50
A33: Paying hostels | B33: 0 | C33: =ROUND($B$3*B32,0) | D33: =ROUND($B$3*C32,0) | E33: =ROUND($B$3*D32,0) | F33: =ROUND($B$3*E32,0) | G33: =ROUND($B$3*F32,0)
A34: Revenue | B34: =$B$2*B33 | C34: =$B$2*C33 | D34: =$B$2*D33 | E34: =$B$2*E33 | F34: =$B$2*F33 | G34: =$B$2*G33
A35: Tech | B35: =$B$9 | C35: =IF(C33>=10,$B$10,0)+$I$30 | D35: =IF(D33>=10,$B$10,0)+$I$30 | E35: =IF(E33>=10,$B$10,0)+$I$30 | F35: =IF(F33>=10,$B$10,0)+$I$30 | G35: =IF(G33>=10,$B$10,0)+$I$30
A36: AI tokens | B36: =$B$8 | C36: =$B$8 | D36: =$B$8 | E36: =$B$8 | F36: =$B$8 | G36: =$B$8
A37: Commission | B37: =0 | C37: =$B$4*MAX(0,C33-B33)+$K$30 | D37: =$B$4*MAX(0,D33-C33)+$K$30 | E37: =$B$4*MAX(0,E33-D33)+$K$30 | F37: =$B$4*MAX(0,F33-E33)+$K$30 | G37: =$B$4*MAX(0,G33-F33)+$K$30
A38: Print | B38: =$B$5*B32 | C38: =$B$5*MAX(0,C32-B32) | D38: =$B$5*MAX(0,D32-C32) | E38: =$B$5*MAX(0,E32-D32) | F38: =$B$5*MAX(0,F32-E32) | G38: =$B$5*MAX(0,G32-F32)
A39: Travel | B39: =2000 | C39: =IF(C32>B32,2000,1000) | D39: =IF(D32>C32,2000,1000) | E39: =IF(E32>D32,2000,1000) | F39: =IF(F32>E32,2000,1000) | G39: =IF(G32>F32,2000,1000)
A40: Ads | B40: =0 | C40: =$M$30 | D40: =$M$30 | E40: =$M$30 | F40: =$M$30 | G40: =$M$30
A41: Rewards | B41: =0 | C41: =0 | D41: =MIN($B$7,$B$6*D33) | E41: =MIN($B$7,$B$6*E33) | F41: =MIN($B$7,$B$6*F33) | G41: =MIN($B$7,$B$6*G33)
A42: Costs | B42: =SUM(B35:B41) | C42: =SUM(C35:C41) | D42: =SUM(D35:D41) | E42: =SUM(E35:E41) | F42: =SUM(F35:F41) | G42: =SUM(G35:G41)
...

Sheet Budget
A1: Bucket (Budget v3: ₹10,000 a month, 2026-10-04) | B1: Cap per month (₹) | C1: Notes
A2: Tech | B2: 0 | C2: ₹0 now. Play ₹2,400 once (from buffer). Supabase Pro ₹2,900 only from 10 paying hostels, paid from revenue
A3: AI tokens | B3: 2300 | C3: Pro-level Claude plan; fill your real bill
A4: Rewards | B4: 1000 | C4: Cash referrals only; next-stay credits are invoice credits
A5: Commission | B5: 1000 | C5: Hold pay for all partners. ₹200/paying owner is paid from that owner's payment
A6: Print | B6: 1500 | C6: ~10 hostels × ₹150
A7: Travel | B7: 2000 | C7: Owner visits
A8: Ads | B8: 0 | C8: Free reels only
A9: Reserve | B9: 2200 | C9: Buffer: pays Play in Oct, then rolls over
A10: Total | B10: =SUM(B2:B9)

Sheet Money in
A1: Date | B1: Month (auto) | C1: Type | D1: Hostel | E1: Plan (₹499/₹999/₹1,499) | F1: Amount (₹) | G1: UTR | H1: Invoice no. | I1: Checked in bank? (Y/N)
B2: =IF(A2="","",TEXT(A2,"yyyy-mm"))
B3: =IF(A3="","",TEXT(A3,"yyyy-mm"))
B4: =IF(A4="","",TEXT(A4,"yyyy-mm"))
B5: =IF(A5="","",TEXT(A5,"yyyy-mm"))
B6: =IF(A6="","",TEXT(A6,"yyyy-mm"))
B7: =IF(A7="","",TEXT(A7,"yyyy-mm"))
B8: =IF(A8="","",TEXT(A8,"yyyy-mm"))
B9: =IF(A9="","",TEXT(A9,"yyyy-mm"))
B10: =IF(A10="","",TEXT(A10,"yyyy-mm"))
B11: =IF(A11="","",TEXT(A11,"yyyy-mm"))
B12: =IF(A12="","",TEXT(A12,"yyyy-mm"))
B13: =IF(A13="","",TEXT(A13,"yyyy-mm"))
... B500: =IF(A500="","",TEXT(A500,"yyyy-mm"))

Sheet Money out
A1: Date | B1: Month (auto) | C1: What | D1: Bucket | E1: Amount (₹) | F1: Paid to | G1: UPI ref / bill no. | H1: Receipt saved? (Y/N)
B2: =IF(A2="","",TEXT(A2,"yyyy-mm"))
B3: =IF(A3="","",TEXT(A3,"yyyy-mm"))
B4: =IF(A4="","",TEXT(A4,"yyyy-mm"))
B5: =IF(A5="","",TEXT(A5,"yyyy-mm"))
B6: =IF(A6="","",TEXT(A6,"yyyy-mm"))
B7: =IF(A7="","",TEXT(A7,"yyyy-mm"))
B8: =IF(A8="","",TEXT(A8,"yyyy-mm"))
B9: =IF(A9="","",TEXT(A9,"yyyy-mm"))
B10: =IF(A10="","",TEXT(A10,"yyyy-mm"))
B11: =IF(A11="","",TEXT(A11,"yyyy-mm"))
B12: =IF(A12="","",TEXT(A12,"yyyy-mm"))
B13: =IF(A13="","",TEXT(A13,"yyyy-mm"))
... B500: =IF(A500="","",TEXT(A500,"yyyy-mm"))

Sheet Rewards
A1: Date | B1: Month (auto) | C1: Tenant (last 4 digits of phone) | D1: Type | E1: Amount (₹) | F1: Paid how (UPI / invoice credit) | G1: Waitlisted? (Y/N) | H1: Checks done (phone, UPI, owner-confirmed)
B2: =IF(A2="","",TEXT(A2,"yyyy-mm"))
B3: =IF(A3="","",TEXT(A3,"yyyy-mm"))
B4: =IF(A4="","",TEXT(A4,"yyyy-mm"))
B5: =IF(A5="","",TEXT(A5,"yyyy-mm"))
B6: =IF(A6="","",TEXT(A6,"yyyy-mm"))
B7: =IF(A7="","",TEXT(A7,"yyyy-mm"))
B8: =IF(A8="","",TEXT(A8,"yyyy-mm"))
B9: =IF(A9="","",TEXT(A9,"yyyy-mm"))
B10: =IF(A10="","",TEXT(A10,"yyyy-mm"))
B11: =IF(A11="","",TEXT(A11,"yyyy-mm"))
B12: =IF(A12="","",TEXT(A12,"yyyy-mm"))
B13: =IF(A13="","",TEXT(A13,"yyyy-mm"))
... B500: =IF(A500="","",TEXT(A500,"yyyy-mm"))

Sheet Partners
A1: Month (YYYY-MM) | B1: Partner | C1: Paid owners | D1: Holds (valid) | E1: Bonus (₹) | F1: Owed (₹) | G1: Paid on | H1: UPI ref | I1: Agreement signed? (Y/N)
F2: =IF(B2="","",C2*200+MIN(D2,100)*20+E2)
F3: =IF(B3="","",C3*200+MIN(D3,100)*20+E3)
F4: =IF(B4="","",C4*200+MIN(D4,100)*20+E4)
F5: =IF(B5="","",C5*200+MIN(D5,100)*20+E5)
F6: =IF(B6="","",C6*200+MIN(D6,100)*20+E6)
F7: =IF(B7="","",C7*200+MIN(D7,100)*20+E7)
F8: =IF(B8="","",C8*200+MIN(D8,100)*20+E8)
F9: =IF(B9="","",C9*200+MIN(D9,100)*20+E9)
F10: =IF(B10="","",C10*200+MIN(D10,100)*20+E10)
F11: =IF(B11="","",C11*200+MIN(D11,100)*20+E11)
F12: =IF(B12="","",C12*200+MIN(D12,100)*20+E12)
F13: =IF(B13="","",C13*200+MIN(D13,100)*20+E13)
... F50: =IF(B50="","",C50*200+MIN(D50,100)*20+E50)

Sheet Summary
A1: Month | B1: Owner income | C1: Money out | D1: Profit / loss | E1: Paid hostels | F1: Tech | G1: AI tokens | H1: Rewards | I1: Commission | J1: Print | K1: Travel | L1: Ads | M1: Rewards over cap? | N1: Bank balance (all in − all out, to date)
A2: 2026-10 | B2: =SUMIFS('Money in'!F:F,'Money in'!B:B,A2,'Money in'!C:C,"Owner plan") | C2: =SUMIF('Money out'!B:B,A2,'Money out'!E:E) | D2: =B2-C2 | E2: =COUNTIFS('Money in'!B:B,A2,'Money in'!C:C,"Owner plan") | F2: =SUMIFS('Money out'!E:E,'Money out'!B:B,A2,'Money out'!D:D,"Tech") | G2: =SUMIFS('Money out'!E:E,'Money out'!B:B,A2,'Money out'!D:D,"AI tokens") | H2: =SUMIFS('Money out'!E:E,'Money out'!B:B,A2,'Money out'!D:D,"Rewards") | I2: =SUMIFS('Money out'!E:E,'Money out'!B:B,A2,'Money out'!D:D,"Commission") | J2: =SUMIFS('Money out'!E:E,'Money out'!B:B,A2,'Money out'!D:D,"Print") | K2: =SUMIFS('Money out'!E:E,'Money out'!B:B,A2,'Money out'!D:D,"Travel") | L2: =SUMIFS('Money out'!E:E,'Money out'!B:B,A2,'Money out'!D:D,"Ads") | M2: =IF(H2>Budget!B4,"OVER","ok") | N2: =SUMIF('Money in'!B:B,A2,'Money in'!F:F)-C2
A3: 2026-11 | B3: =SUMIFS('Money in'!F:F,'Money in'!B:B,A3,'Money in'!C:C,"Owner plan") | C3: =SUMIF('Money out'!B:B,A3,'Money out'!E:E) | D3: =B3-C3 | E3: =COUNTIFS('Money in'!B:B,A3,'Money in'!C:C,"Owner plan") | F3: =SUMIFS('Money out'!E:E,'Money out'!B:B,A3,'Money out'!D:D,"Tech") | G3: =SUMIFS('Money out'!E:E,'Money out'!B:B,A3,'Money out'!D:D,"AI tokens") | H3: =SUMIFS('Money out'!E:E,'Money out'!B:B,A3,'Money out'!D:D,"Rewards") | I3: =SUMIFS('Money out'!E:E,'Money out'!B:B,A3,'Money out'!D:D,"Commission") | J3: =SUMIFS('Money out'!E:E,'Money out'!B:B,A3,'Money out'!D:D,"Print") | K3: =SUMIFS('Money out'!E:E,'Money out'!B:B,A3,'Money out'!D:D,"Travel") | L3: =SUMIFS('Money out'!E:E,'Money out'!B:B,A3,'Money out'!D:D,"Ads") | M3: =IF(H3>Budget!B4,"OVER","ok") | N3: =N2+SUMIF('Money in'!B:B,A3,'Money in'!F:F)-C3
A4: 2026-12 | B4: =SUMIFS('Money in'!F:F,'Money in'!B:B,A4,'Money in'!C:C,"Owner plan") | C4: =SUMIF('Money out'!B:B,A4,'Money out'!E:E) | D4: =B4-C4 | E4: =COUNTIFS('Money in'!B:B,A4,'Money in'!C:C,"Owner plan") | F4: =SUMIFS('Money out'!E:E,'Money out'!B:B,A4,'Money out'!D:D,"Tech") | G4: =SUMIFS('Money out'!E:E,'Money out'!B:B,A4,'Money out'!D:D,"AI tokens") | H4: =SUMIFS('Money out'!E:E,'Money out'!B:B,A4,'Money out'!D:D,"Rewards") | I4: =SUMIFS('Money out'!E:E,'Money out'!B:B,A4,'Money out'!D:D,"Commission") | J4: =SUMIFS('Money out'!E:E,'Money out'!B:B,A4,'Money out'!D:D,"Print") | K4: =SUMIFS('Money out'!E:E,'Money out'!B:B,A4,'Money out'!D:D,"Travel") | L4: =SUMIFS('Money out'!E:E,'Money out'!B:B,A4,'Money out'!D:D,"Ads") | M4: =IF(H4>Budget!B4,"OVER","ok") | N4: =N3+SUMIF('Money in'!B:B,A4,'Money in'!F:F)-C4
A5: 2027-01 | B5: =SUMIFS('Money in'!F:F,'Money in'!B:B,A5,'Money in'!C:C,"Owner plan") | C5: =SUMIF('Money out'!B:B,A5,'Money out'!E:E) | D5: =B5-C5 | E5: =COUNTIFS('Money in'!B:B,A5,'Money in'!C:C,"Owner plan") | F5: =SUMIFS('Money out'!E:E,'Money out'!B:B,A5,'Money out'!D:D,"Tech") | G5: =SUMIFS('Money out'!E:E,'Money out'!B:B,A5,'Money out'!D:D,"AI tokens") | H5: =SUMIFS('Money out'!E:E,'Money out'!B:B,A5,'Money out'!D:D,"Rewards") | I5: =SUMIFS('Money out'!E:E,'Money out'!B:B,A5,'Money out'!D:D,"Commission") | J5: =SUMIFS('Money out'!E:E,'Money out'!B:B,A5,'Money out'!D:D,"Print") | K5: =SUMIFS('Money out'!E:E,'Money out'!B:B,A5,'Money out'!D:D,"Travel") | L5: =SUMIFS('Money out'!E:E,'Money out'!B:B,A5,'Money out'!D:D,"Ads") | M5: =IF(H5>Budget!B4,"OVER","ok") | N5: =N4+SUMIF('Money in'!B:B,A5,'Money in'!F:F)-C5
A6: 2027-02 | B6: =SUMIFS('Money in'!F:F,'Money in'!B:B,A6,'Money in'!C:C,"Owner plan") | C6: =SUMIF('Money out'!B:B,A6,'Money out'!E:E) | D6: =B6-C6 | E6: =COUNTIFS('Money in'!B:B,A6,'Money in'!C:C,"Owner plan") | F6: =SUMIFS('Money out'!E:E,'Money out'!B:B,A6,'Money out'!D:D,"Tech") | G6: =SUMIFS('Money out'!E:E,'Money out'!B:B,A6,'Money out'!D:D,"AI tokens") | H6: =SUMIFS('Money out'!E:E,'Money out'!B:B,A6,'Money out'!D:D,"Rewards") | I6: =SUMIFS('Money out'!E:E,'Money out'!B:B,A6,'Money out'!D:D,"Commission") | J6: =SUMIFS('Money out'!E:E,'Money out'!B:B,A6,'Money out'!D:D,"Print") | K6: =SUMIFS('Money out'!E:E,'Money out'!B:B,A6,'Money out'!D:D,"Travel") | L6: =SUMIFS('Money out'!E:E,'Money out'!B:B,A6,'Money out'!D:D,"Ads") | M6: =IF(H6>Budget!B4,"OVER","ok") | N6: =N5+SUMIF('Money in'!B:B,A6,'Money in'!F:F)-C6
A7: 2027-03 | B7: =SUMIFS('Money in'!F:F,'Money in'!B:B,A7,'Money in'!C:C,"Owner plan") | C7: =SUMIF('Money out'!B:B,A7,'Money out'!E:E) | D7: =B7-C7 | E7: =COUNTIFS('Money in'!B:B,A7,'Money in'!C:C,"Owner plan") | F7: =SUMIFS('Money out'!E:E,'Money out'!B:B,A7,'Money out'!D:D,"Tech") | G7: =SUMIFS('Money out'!E:E,'Money out'!B:B,A7,'Money out'!D:D,"AI tokens") | H7: =SUMIFS('Money out'!E:E,'Money out'!B:B,A7,'Money out'!D:D,"Rewards") | I7: =SUMIFS('Money out'!E:E,'Money out'!B:B,A7,'Money out'!D:D,"Commission") | J7: =SUMIFS('Money out'!E:E,'Money out'!B:B,A7,'Money out'!D:D,"Print") | K7: =SUMIFS('Money out'!E:E,'Money out'!B:B,A7,'Money out'!D:D,"Travel") | L7: =SUMIFS('Money out'!E:E,'Money out'!B:B,A7,'Money out'!D:D,"Ads") | M7: =IF(H7>Budget!B4,"OVER","ok") | N7: =N6+SUMIF('Money in'!B:B,A7,'Money in'!F:F)-C7
A8: 2027-04 | B8: =SUMIFS('Money in'!F:F,'Money in'!B:B,A8,'Money in'!C:C,"Owner plan") | C8: =SUMIF('Money out'!B:B,A8,'Money out'!E:E) | D8: =B8-C8 | E8: =COUNTIFS('Money in'!B:B,A8,'Money in'!C:C,"Owner plan") | F8: =SUMIFS('Money out'!E:E,'Money out'!B:B,A8,'Money out'!D:D,"Tech") | G8: =SUMIFS('Money out'!E:E,'Money out'!B:B,A8,'Money out'!D:D,"AI tokens") | H8: =SUMIFS('Money out'!E:E,'Money out'!B:B,A8,'Money out'!D:D,"Rewards") | I8: =SUMIFS('Money out'!E:E,'Money out'!B:B,A8,'Money out'!D:D,"Commission") | J8: =SUMIFS('Money out'!E:E,'Money out'!B:B,A8,'Money out'!D:D,"Print") | K8: =SUMIFS('Money out'!E:E,'Money out'!B:B,A8,'Money out'!D:D,"Travel") | L8: =SUMIFS('Money out'!E:E,'Money out'!B:B,A8,'Money out'!D:D,"Ads") | M8: =IF(H8>Budget!B4,"OVER","ok") | N8: =N7+SUMIF('Money in'!B:B,A8,'Money in'!F:F)-C8
A9: 2027-05 | B9: =SUMIFS('Money in'!F:F,'Money in'!B:B,A9,'Money in'!C:C,"Owner plan") | C9: =SUMIF('Money out'!B:B,A9,'Money out'!E:E) | D9: =B9-C9 | E9: =COUNTIFS('Money in'!B:B,A9,'Money in'!C:C,"Owner plan") | F9: =SUMIFS('Money out'!E:E,'Money out'!B:B,A9,'Money out'!D:D,"Tech") | G9: =SUMIFS('Money out'!E:E,'Money out'!B:B,A9,'Money out'!D:D,"AI tokens") | H9: =SUMIFS('Money out'!E:E,'Money out'!B:B,A9,'Money out'!D:D,"Rewards") | I9: =SUMIFS('Money out'!E:E,'Money out'!B:B,A9,'Money out'!D:D,"Commission") | J9: =SUMIFS('Money out'!E:E,'Money out'!B:B,A9,'Money out'!D:D,"Print") | K9: =SUMIFS('Money out'!E:E,'Money out'!B:B,A9,'Money out'!D:D,"Travel") | L9: =SUMIFS('Money out'!E:E,'Money out'!B:B,A9,'Money out'!D:D,"Ads") | M9: =IF(H9>Budget!B4,"OVER","ok") | N9: =N8+SUMIF('Money in'!B:B,A9,'Money in'!F:F)-C9
A10: 2027-06 | B10: =SUMIFS('Money in'!F:F,'Money in'!B:B,A10,'Money in'!C:C,"Owner plan") | C10: =SUMIF('Money out'!B:B,A10,'Money out'!E:E) | D10: =B10-C10 | E10: =COUNTIFS('Money in'!B:B,A10,'Money in'!C:C,"Owner plan") | F10: =SUMIFS('Money out'!E:E,'Money out'!B:B,A10,'Money out'!D:D,"Tech") | G10: =SUMIFS('Money out'!E:E,'Money out'!B:B,A10,'Money out'!D:D,"AI tokens") | H10: =SUMIFS('Money out'!E:E,'Money out'!B:B,A10,'Money out'!D:D,"Rewards") | I10: =SUMIFS('Money out'!E:E,'Money out'!B:B,A10,'Money out'!D:D,"Commission") | J10: =SUMIFS('Money out'!E:E,'Money out'!B:B,A10,'Money out'!D:D,"Print") | K10: =SUMIFS('Money out'!E:E,'Money out'!B:B,A10,'Money out'!D:D,"Travel") | L10: =SUMIFS('Money out'!E:E,'Money out'!B:B,A10,'Money out'!D:D,"Ads") | M10: =IF(H10>Budget!B4,"OVER","ok") | N10: =N9+SUMIF('Money in'!B:B,A10,'Money in'!F:F)-C10
A11: 2027-07 | B11: =SUMIFS('Money in'!F:F,'Money in'!B:B,A11,'Money in'!C:C,"Owner plan") | C11: =SUMIF('Money out'!B:B,A11,'Money out'!E:E) | D11: =B11-C11 | E11: =COUNTIFS('Money in'!B:B,A11,'Money in'!C:C,"Owner plan") | F11: =SUMIFS('Money out'!E:E,'Money out'!B:B,A11,'Money out'!D:D,"Tech") | G11: =SUMIFS('Money out'!E:E,'Money out'!B:B,A11,'Money out'!D:D,"AI tokens") | H11: =SUMIFS('Money out'!E:E,'Money out'!B:B,A11,'Money out'!D:D,"Rewards") | I11: =SUMIFS('Money out'!E:E,'Money out'!B:B,A11,'Money out'!D:D,"Commission") | J11: =SUMIFS('Money out'!E:E,'Money out'!B:B,A11,'Money out'!D:D,"Print") | K11: =SUMIFS('Money out'!E:E,'Money out'!B:B,A11,'Money out'!D:D,"Travel") | L11: =SUMIFS('Money out'!E:E,'Money out'!B:B,A11,'Money out'!D:D,"Ads") | M11: =IF(H11>Budget!B4,"OVER","ok") | N11: =N10+SUMIF('Money in'!B:B,A11,'Money in'!F:F)-C11
A12: 2027-08 | B12: =SUMIFS('Money in'!F:F,'Money in'!B:B,A12,'Money in'!C:C,"Owner plan") | C12: =SUMIF('Money out'!B:B,A12,'Money out'!E:E) | D12: =B12-C12 | E12: =COUNTIFS('Money in'!B:B,A12,'Money in'!C:C,"Owner plan") | F12: =SUMIFS('Money out'!E:E,'Money out'!B:B,A12,'Money out'!D:D,"Tech") | G12: =SUMIFS('Money out'!E:E,'Money out'!B:B,A12,'Money out'!D:D,"AI tokens") | H12: =SUMIFS('Money out'!E:E,'Money out'!B:B,A12,'Money out'!D:D,"Rewards") | I12: =SUMIFS('Money out'!E:E,'Money out'!B:B,A12,'Money out'!D:D,"Commission") | J12: =SUMIFS('Money out'!E:E,'Money out'!B:B,A12,'Money out'!D:D,"Print") | K12: =SUMIFS('Money out'!E:E,'Money out'!B:B,A12,'Money out'!D:D,"Travel") | L12: =SUMIFS('Money out'!E:E,'Money out'!B:B,A12,'Money out'!D:D,"Ads") | M12: =IF(H12>Budget!B4,"OVER","ok") | N12: =N11+SUMIF('Money in'!B:B,A12,'Money in'!F:F)-C12
A13: 2027-09 | B13: =SUMIFS('Money in'!F:F,'Money in'!B:B,A13,'Money in'!C:C,"Owner plan") | C13: =SUMIF('Money out'!B:B,A13,'Money out'!E:E) | D13: =B13-C13 | E13: =COUNTIFS('Money in'!B:B,A13,'Money in'!C:C,"Owner plan") | F13: =SUMIFS('Money out'!E:E,'Money out'!B:B,A13,'Money out'!D:D,"Tech") | G13: =SUMIFS('Money out'!E:E,'Money out'!B:B,A13,'Money out'!D:D,"AI tokens") | H13: =SUMIFS('Money out'!E:E,'Money out'!B:B,A13,'Money out'!D:D,"Rewards") | I13: =SUMIFS('Money out'!E:E,'Money out'!B:B,A13,'Money out'!D:D,"Commission") | J13: =SUMIFS('Money out'!E:E,'Money out'!B:B,A13,'Money out'!D:D,"Print") | K13: =SUMIFS('Money out'!E:E,'Money out'!B:B,A13,'Money out'!D:D,"Travel") | L13: =SUMIFS('Money out'!E:E,'Money out'!B:B,A13,'Money out'!D:D,"Ads") | M13: =IF(H13>Budget!B4,"OVER","ok") | N13: =N12+SUMIF('Money in'!B:B,A13,'Money in'!F:F)-C13
A15: Note: Profit / loss counts only owner income. Put your monthly ₹40k in 'Money in' with Type = Founder top-up, so the bank balance column matches the real bank account.
